2024-05-15 12:54:09,051 - INFO - Conexion establecida
2024-05-15 12:54:09,052 - ERROR - Ocurrió un error al intentar probar la consulta
Traceback (most recent call last):
  File "C:\PROYECTOS\PyCharm\pythonrun\tfm\sesiones\sesiones.py", line 32, in probar_connection
    cursor = conn.execute('SELECT * FROM sesiones limit 1').fetchall()
             ^^^^^^^^^^^^^^^^^^^^^^^^^^^^^^^^^^^^^^^^^^^^^^
sqlite3.OperationalError: no such table: sesiones
2024-05-15 12:54:09,056 - INFO - Conexion establecida
2024-05-15 12:54:09,057 - ERROR - Ocurrió un error al obtener datos para la sesion 1234567890acbd
Traceback (most recent call last):
  File "C:\PROYECTOS\PyCharm\pythonrun\tfm\sesiones\sesiones.py", line 41, in obtener_mensajes_por_sesion
    res = conn.execute(f"SELECT * FROM sesiones where id_session='{id_session}';").fetchall()
          ^^^^^^^^^^^^^^^^^^^^^^^^^^^^^^^^^^^^^^^^^^^^^^^^^^^^^^^^^^^^^^^^^^^^^^^^
sqlite3.OperationalError: no such table: sesiones
2024-05-15 12:54:09,065 - INFO - Conexion establecida
2024-05-15 12:54:09,065 - ERROR - Ocurrió un error al insertar los datos para la sesion 1234567890acbd
Traceback (most recent call last):
  File "C:\PROYECTOS\PyCharm\pythonrun\tfm\sesiones\sesiones.py", line 59, in aniadir_mensajes_por_sesion
    cursor.execute(consulta, (id_session, prompt))
sqlite3.OperationalError: no such table: sesiones
2024-05-15 12:54:09,066 - INFO - Conexion establecida
2024-05-15 12:54:09,067 - ERROR - Ocurrió un error al obtener datos para la sesion 1234567890acbd
Traceback (most recent call last):
  File "C:\PROYECTOS\PyCharm\pythonrun\tfm\sesiones\sesiones.py", line 69, in aniadir_mensajes_por_sesion
    res = conn.execute(f"SELECT * FROM sesiones where id_session='{id_session}';").fetchall()
          ^^^^^^^^^^^^^^^^^^^^^^^^^^^^^^^^^^^^^^^^^^^^^^^^^^^^^^^^^^^^^^^^^^^^^^^^
sqlite3.OperationalError: no such table: sesiones
2024-05-15 12:54:18,965 - INFO - Conexion establecida
2024-05-15 12:54:18,966 - ERROR - Ocurrió un error al intentar probar la consulta
Traceback (most recent call last):
  File "C:\PROYECTOS\PyCharm\pythonrun\tfm\sesiones\sesiones.py", line 32, in probar_connection
    cursor = conn.execute('SELECT * FROM sesiones limit 1').fetchall()
             ^^^^^^^^^^^^^^^^^^^^^^^^^^^^^^^^^^^^^^^^^^^^^^
sqlite3.OperationalError: no such table: sesiones
2024-05-15 12:54:18,970 - INFO - Conexion establecida
2024-05-15 12:54:18,970 - ERROR - Ocurrió un error al obtener datos para la sesion 1234567890acbd
Traceback (most recent call last):
  File "C:\PROYECTOS\PyCharm\pythonrun\tfm\sesiones\sesiones.py", line 41, in obtener_mensajes_por_sesion
    res = conn.execute(f"SELECT * FROM sesiones where id_session='{id_session}';").fetchall()
          ^^^^^^^^^^^^^^^^^^^^^^^^^^^^^^^^^^^^^^^^^^^^^^^^^^^^^^^^^^^^^^^^^^^^^^^^
sqlite3.OperationalError: no such table: sesiones
2024-05-15 12:54:18,971 - INFO - Conexion establecida
2024-05-15 12:54:18,971 - ERROR - Ocurrió un error al insertar los datos para la sesion 1234567890acbd
Traceback (most recent call last):
  File "C:\PROYECTOS\PyCharm\pythonrun\tfm\sesiones\sesiones.py", line 59, in aniadir_mensajes_por_sesion
    cursor.execute(consulta, (id_session, prompt))
sqlite3.OperationalError: no such table: sesiones
2024-05-15 12:54:18,972 - INFO - Conexion establecida
2024-05-15 12:54:18,973 - ERROR - Ocurrió un error al obtener datos para la sesion 1234567890acbd
Traceback (most recent call last):
  File "C:\PROYECTOS\PyCharm\pythonrun\tfm\sesiones\sesiones.py", line 69, in aniadir_mensajes_por_sesion
    res = conn.execute(f"SELECT * FROM sesiones where id_session='{id_session}';").fetchall()
          ^^^^^^^^^^^^^^^^^^^^^^^^^^^^^^^^^^^^^^^^^^^^^^^^^^^^^^^^^^^^^^^^^^^^^^^^
sqlite3.OperationalError: no such table: sesiones
